<?xml version="1.0"?> 
<robot name="simplecar">

    <material name="blue">
        <color rgba="0.6 0.7 0.8 0.7"/>
    </material>

    <material name="black">
        <color rgba="0 0 0 1"/>
    </material>

    <!-- Base Frame of Car --> 
    <link name="base_link">
        <visual>
            <geometry>
                <box size="0.5 0.3 0.1"/>
            </geometry>
            <material name="blue"/>
        </visual> 
    </link>

    <!-- Left Back Wheel : black color -->
    <link name="left_back_wheel">
        <visual>
            <geometry>
                <cylinder length="0.05" radius="0.1"/>
            </geometry>
            <material name="black"/>
            <origin rpy="1.57075 1.57075 0"/>
            <!-- rpy angles 회전각 : https://commons.wikimedia.org/wiki/RPY_angles , 단위 : radian-->
        </visual>
        <collision>
            <geometry>
                <cylinder length="0.05" radius="0.1"/>
            </geometry>
            <origin rpy="1.57075 1.57075 0"/>
        </collision>
    </link>

    <!-- Left Front Wheel : black color -->
    <link name="left_front_wheel">
        <visual>
            <geometry>
                <cylinder length="0.05" radius="0.1"/>
            </geometry>
            <material name="black"/>
            <origin rpy="1.57075 1.57075 0"/>
        </visual>
        <collision>
            <geometry>
                <cylinder length="0.05" radius="0.1"/>
            </geometry>
            <origin rpy="1.57075 1.57075 0"/>
        </collision>    
        <inertial>
            <origin rpy="1.57075 1.57075 0"/>
            <mass value="0.3"/>
            <inertia ixx="0.4" ixy="0" ixz="0" iyy="0.4" iyz="0.0" izz="0.2"/>
        </inertial>    
    </link>

    <!-- Right Back Wheel -->
    <link name="right_back_wheel">
        <visual>
            <geometry>
                <cylinder length="0.05" radius="0.1"/>
            </geometry>
            <origin rpy="1.57075 1.57075 0"/>
        </visual>
        <collision>
            <geometry>
                <cylinder length="0.05" radius="0.1"/>
            </geometry>
            <origin rpy="1.57075 1.57075 0"/>
        </collision>        
        <inertial>
            <origin rpy="1.57075 1.57075 0"/>
            <mass value="0.3"/>
            <inertia ixx="0.4" ixy="0" ixz="0" iyy="0.4" iyz="0.0" izz="0.2"/>
        </inertial>    
    </link>

    <!-- Left Front Wheel -->
    <link name="right_front_wheel">
        <visual>
            <geometry>
                <cylinder length="0.05" radius="0.1"/>
            </geometry>
            <origin rpy="1.57075 1.57075 0"/>
        </visual>
        <collision>
            <geometry>
                <cylinder length="0.05" radius="0.1"/>
            </geometry>
            <origin rpy="1.57075 1.57075 0"/>
        </collision>
        <inertial>
            <origin rpy="1.57075 1.57075 0"/>
            <mass value="0.3"/>
            <inertia ixx="0.4" ixy="0" ixz="0" iyy="0.4" iyz="0.0" izz="0.2"/>
        </inertial>    
    </link>


    <joint name="base_to_left_back_wheel" type="continuous"> <!-- continuos type : -->
        <parent link="base_link"/>
        <child link="left_back_wheel"/>
        <axis xyz="0 1 0"/>             <!-- 회전축 -->
        <origin xyz="-0.2 -0.175 0"/>   <!-- joint 할 위치 -->
    </joint>

    <joint name="base_to_left_front_wheel" type="continuous">
        <parent link="base_link"/>
        <child link="left_front_wheel"/>
        <axis xyz="0 1 0"/>
        <origin xyz="0.2 -0.175 0"/>
    </joint>

    <joint name="base_to_right_back_wheel" type="continuous">
        <parent link="base_link"/>
        <child link="right_back_wheel"/>
        <axis xyz="0 1 0"/>
        <origin xyz="-0.2 0.175 0"/>
    </joint>

    <joint name="base_to_right_front_wheel" type="continuous">
        <parent link="base_link"/>
        <child link="right_front_wheel"/>
        <axis xyz="0 1 0"/>
        <origin xyz="0.2 0.175 0"/>
    </joint>


</robot>